Workbook

Sheet Resumen
B2: Relación materias – simuladores CompanyGame
B3: Corporación Universitaria de la Costa (CUC) · Administración de Empresas, Administración de Servicios de Salud, Contaduría Pública, Mercadeo y Publicidad, Negocios Internacionales
B4: Análisis del plan de estudios de cada pregrado (presencial, Barranquilla) frente al catálogo de simuladores CompanyGame
B6: Programa | C6: N.º de materias | D6: Encaje perfecto | E6: Encaje parcial | F6: No encaja / a desarrollar | G6: % con simulador CG
B7: Administración de Empresas | C7: =COUNTA('Administración de Empresas'!$B$3:$B$200) -> 46 | D7: =COUNTIF('Administración de Empresas'!$F$3:$F$200,"Encaje perfecto") -> 6 | E7: =COUNTIF('Administración de Empresas'!$F$3:$F$200,"Encaje parcial") -> 3 | F7: =COUNTIF('Administración de Empresas'!$F$3:$F$200,"No encaja") -> 37 | G7: =IFERROR((D7+E7)/C7,0) -> 0.19565217
B8: Administración de Servicios de Salud | C8: =COUNTA('Adm. de Servicios de Salud'!$B$3:$B$200) -> 46 | D8: =COUNTIF('Adm. de Servicios de Salud'!$F$3:$F$200,"Encaje perfecto") -> 3 | E8: =COUNTIF('Adm. de Servicios de Salud'!$F$3:$F$200,"Encaje parcial") -> 2 | F8: =COUNTIF('Adm. de Servicios de Salud'!$F$3:$F$200,"No encaja") -> 41 | G8: =IFERROR((D8+E8)/C8,0) -> 0.10869565
B9: Contaduría Pública | C9: =COUNTA('Contaduría Pública'!$B$3:$B$200) -> 48 | D9: =COUNTIF('Contaduría Pública'!$F$3:$F$200,"Encaje perfecto") -> 2 | E9: =COUNTIF('Contaduría Pública'!$F$3:$F$200,"Encaje parcial") -> 2 | F9: =COUNTIF('Contaduría Pública'!$F$3:$F$200,"No encaja") -> 44 | G9: =IFERROR((D9+E9)/C9,0) -> 0.083333333
B10: Mercadeo y Publicidad | C10: =COUNTA('Mercadeo y Publicidad'!$B$3:$B$200) -> 46 | D10: =COUNTIF('Mercadeo y Publicidad'!$F$3:$F$200,"Encaje perfecto") -> 4 | E10: =COUNTIF('Mercadeo y Publicidad'!$F$3:$F$200,"Encaje parcial") -> 4 | F10: =COUNTIF('Mercadeo y Publicidad'!$F$3:$F$200,"No encaja") -> 38 | G10: =IFERROR((D10+E10)/C10,0) -> 0.17391304
B11: Negocios Internacionales | C11: =COUNTA('Negocios Internacionales'!$B$3:$B$200) -> 47 | D11: =COUNTIF('Negocios Internacionales'!$F$3:$F$200,"Encaje perfecto") -> 3 | E11: =COUNTIF('Negocios Internacionales'!$F$3:$F$200,"Encaje parcial") -> 2 | F11: =COUNTIF('Negocios Internacionales'!$F$3:$F$200,"No encaja") -> 42 | G11: =IFERROR((D11+E11)/C11,0) -> 0.10638298
B12: TOTAL | C12: =SUM(C7:C11) -> 233 | D12: =SUM(D7:D11) -> 18 | E12: =SUM(E7:E11) -> 13 | F12: =SUM(F7:F11) -> 202 | G12: =IFERROR((D12+E12)/C12,0) -> 0.13304721
B14: Convención de la columna 'Grado de ajuste':
B15: Encaje perfecto | C15: Un simulador CompanyGame cubre directamente la materia
B16: Encaje parcial | C16: Un simulador CG cubre parte de la materia; se sugiere complementar/desarrollar
B17: No encaja | C17: Ningún simulador CG aplica; se propone el tipo de simulador a desarrollar
B19: Notas metodológicas
B20: · La columna 'Semestre' corresponde al avance del plan de estudios de cada pregrado.
B21: · Mallas tomadas de las infografías oficiales 'Plan de estudios' de la Corporación Universitaria de la Costa (CUC):
B22: Administración de Empresas (8 sem, 145 créditos), Administración de Servicios de Salud (9 sem, 145 créditos),
B23: Contaduría Pública (8 sem, 143 créditos), Mercadeo y Publicidad (8 sem, 145 créditos) y Negocios Internacionales
B24: (8 sem, 148 créditos). Los 5 programas se ofertan únicamente de forma presencial en Barranquilla — no existe
B25: variante virtual, por lo que cada programa se mapea en una sola malla.
B26: · Catálogo de simuladores tomado de companygame.com (8 categorías; ver hoja 'Catálogo CompanyGame'),
B27: el mismo cuadro de referencia usado para los mapeos de Universidad del Valle y Corporación Universitaria Americana.
B28: · Niveles CG: N1-2 Intro · N3-4 Avanzado · N5 Graduate · N6-7 Postgrado/Executive.
B29: · El catálogo no tiene categoría de RR.HH., de gestión pública ni de sector salud: las materias de talento humano,
B30: liderazgo, gestión pública/estatal y las asignaturas clínico-administrativas propias de Administración de Servicios
... B38: Banca (ContaTrainer, Corbatul) y Negocios y Estrategia (T-Shirt, Business21, Business Global), respectivamente.

Sheet Catálogo CompanyGame
A1: Catálogo de simuladores CompanyGame
A2: Fuente: companygame.com
A3: Categoría | B3: Simulador | C3: Nivel | D3: Descripción / área temática
A4: Negocios y Estrategia | B4: T-Shirt | C4: N1-2 | D4: Introducción a la gestión empresarial (sector textil)
A5: Negocios y Estrategia | B5: Sunny Day | C5: N1-2 | D5: Introducción a la gestión; visión global (bebidas/consumo)
A6: Negocios y Estrategia | B6: Energy&Co | C6: N1-2 | D6: Introducción a la gestión empresarial (sector energético)
A7: Negocios y Estrategia | B7: Business21 | C7: N3-4 | D7: Dirección general intermedia; visión integral
A8: Negocios y Estrategia | B8: Business Global | C8: N5 | D8: Dirección general avanzada; simulación gerencial integral
A9: Negocios y Estrategia | B9: Business Strategy | C9: N6-7 | D9: Estrategia empresarial (executive/posgrado)
A10: Marketing y Ventas | B10: MarketGame | C10: N1-2 | D10: Introducción al marketing y decisiones comerciales
A11: Marketing y Ventas | B11: Coffee Time | C11: N1-2 | D11: Marketing y retail (sector cafetería)
A12: Marketing y Ventas | B12: Food Company | C12: N3-4 | D12: Marketing estratégico sector alimentos
A13: Marketing y Ventas | B13: SalesManager | C13: N3-4 | D13: Gestión de la fuerza de ventas
A14: Marketing y Ventas | B14: TechCompany | C14: N5 | D14: Marketing sector tecnológico
... A44: Operaciones | B44: Milk Factory | C44: N5 | D44: Gestión de operaciones y producción (planta láctea)

Sheet Administración de Empresas
A1: Administración de Empresas · Corporación Universitaria de la Costa (CUC) — presencial, Barranquilla
A2: Semestre | B2: Materia | C2: Área temática | D2: Simulador CompanyGame que encaja | E2: Nivel CG | F2: Grado de ajuste | G2: Tipo de simulador a desarrollar (si no encaja / parcial) | H2: Observación
A3: 1 | B3: Razonamiento lógico matemático I | C3: Cuantitativa | D3: — | E3: — | F3: No encaja | G3: Herramienta de cálculo aplicado a decisiones administrativas
A4: 1 | B4: Pensamiento Administrativo | C4: Administración | D4: T-Shirt | E4: N1-2 | F4: Encaje perfecto
A5: 1 | B5: Entorno Económico de los Negocios | C5: Economía | D5: — | E5: — | F5: No encaja | G5: Caso de análisis de entorno macroeconómico
A6: 1 | B6: Contabilidad financiera | C6: Contabilidad | D6: ContaTrainer | E6: N1-2 | F6: Encaje perfecto
A7: 1 | B7: Electiva de humanidades I | C7: Humanidades | D7: — | E7: — | F7: No encaja
A8: 1 | B8: BIVE I | C8: Bienestar/Formación integral | D8: — | E8: — | F8: No encaja
A9: 2 | B9: Matemática Financiera | C9: Cuantitativa | D9: Advisor Jr. | E9: N1-2 | F9: Encaje parcial | G9: Calculadora financiera / casos de valor del dinero en el tiempo
A10: 2 | B10: Marco Legal Empresarial | C10: Jurídica | D10: — | E10: — | F10: No encaja
A11: 2 | B11: Costos | C11: Contabilidad | D11: — | E11: — | F11: No encaja | G11: Complementar con módulo específico de costeo por producto
A12: 2 | B12: Economía Para La Toma De Decisiones | C12: Economía | D12: — | E12: — | F12: No encaja
A13: 2 | B13: Electiva de humanidades II | C13: Humanidades | D13: — | E13: — | F13: No encaja
A14: 2 | B14: BIVE II | C14: Bienestar/Formación integral | D14: — | E14: — | F14: No encaja
A15: 3 | B15: Presupuesto | C15: Finanzas | D15: — | E15: — | F15: No encaja | G15: Complementar con caso de presupuesto maestro
A16: 3 | B16: Mercadeo Y Creación De Valor | C16: Marketing | D16: Coffee Time | E16: N1-2 | F16: Encaje perfecto
A17: 3 | B17: Gestión Organizacional Ágil | C17: Administración | D17: — | E17: — | F17: No encaja
A18: 3 | B18: Tecnologías para la Gestión Empresarial | C18: Digital | D18: — | E18: — | F18: No encaja
A19: 3 | B19: Comportamiento y Gestión Del Talento | C19: Talento Humano | D19: — | E19: — | F19: No encaja | G19: Simulador de gestión de equipos y clima organizacional
A20: 3 | B20: Electiva de humanidades III | C20: Humanidades | D20: — | E20: — | F20: No encaja
A21: 3 | B21: BIVE III | C21: Bienestar/Formación integral | D21: — | E21: — | F21: No encaja
A22: 4 | B22: Investigación De Mercados | C22: Investigación | D22: FOCUS | E22: N5 | F22: Encaje perfecto
A23: 4 | B23: Dinámicas de Integración Global | C23: Internacional | D23: — | E23: — | F23: No encaja
A24: 4 | B24: Gestión De Operaciones y Logística | C24: Operaciones | D24: — | E24: — | F24: No encaja | G24: Complementar con módulo de logística de distribución
A25: 4 | B25: Gerencia Financiera | C25: Finanzas | D25: Corbatul | E25: N3-4 | F25: Encaje perfecto
A26: 4 | B26: Estadística Para La Gestión | C26: Cuantitativa | D26: — | E26: — | F26: No encaja
A27: 4 | B27: Estrategia Y Creación De Valor | C27: Administración | D27: Business21 | E27: N3-4 | F27: Encaje perfecto
A28: 4 | B28: BIVE IV | C28: Bienestar/Formación integral | D28: — | E28: — | F28: No encaja
A29: 5 | B29: Transformación Digital e IA | C29: Digital | D29: — | E29: — | F29: No encaja
A30: 5 | B30: Talent Analytics & Strategic HR | C30: Talento Humano | D30: — | E30: — | F30: No encaja | G30: Simulador de analítica de datos de RR.HH.
A31: 5 | B31: Dirección Estratégica De Mercadeo | C31: Marketing | D31: — | E31: — | F31: No encaja
A32: 5 | B32: Innovation And Business Models | C32: Emprendimiento | D32: — | E32: — | F32: No encaja
A33: 5 | B33: Electiva Gerencial I | C33: Electiva | D33: — | E33: — | F33: No encaja | G33: Contenido variable según la línea gerencial elegida; evaluar caso a caso
A34: 5 | B34: Suficiencia Segundo Idioma I | C34: Idiomas | D34: — | E34: — | F34: No encaja
A35: 6 | B35: Sustainable Talent and Global Governance | C35: Talento Humano | D35: — | E35: — | F35: No encaja | G35: Simulador de gobierno corporativo y talento sostenible
A36: 6 | B36: Innovación Sostenible | C36: Sostenibilidad/ESG | D36: — | E36: — | F36: No encaja
A37: 6 | B37: Gerencia De La Cadena De Suministro | C37: Operaciones | D37: — | E37: — | F37: No encaja
A38: 6 | B38: Diseño Y Formulación De Proyectos | C38: Práctica/Proyecto | D38: Fitness Gym | E38: N3-4 | F38: Encaje parcial | G38: Simulador de gestión de proyectos (alcance, tiempo, costo)
A39: 6 | B39: Electiva gerencial II | C39: Electiva | D39: — | E39: — | F39: No encaja | G39: Contenido variable según la línea gerencial elegida; evaluar caso a caso
A40: 6 | B40: Suficiencia del segundo idioma II | C40: Idiomas | D40: — | E40: — | F40: No encaja
...

Sheet Adm. de Servicios de Salud
A1: Administración de Servicios de Salud · Corporación Universitaria de la Costa (CUC) — presencial, Barranquilla
A2: Semestre | B2: Materia | C2: Área temática | D2: Simulador CompanyGame que encaja | E2: Nivel CG | F2: Grado de ajuste | G2: Tipo de simulador a desarrollar (si no encaja / parcial) | H2: Observación
A3: 1 | B3: Fundamentos de Mercadeo | C3: Marketing | D3: Coffee Time | E3: N1-2 | F3: Encaje perfecto
A4: 1 | B4: Pensamiento lógico matemático | C4: Cuantitativa | D4: — | E4: — | F4: No encaja
A5: 1 | B5: Fundamentos administrativos | C5: Administración | D5: T-Shirt | E5: N1-2 | F5: Encaje perfecto
A6: 1 | B6: Sistemas de salud | C6: Salud | D6: — | E6: — | F6: No encaja | G6: Simulador de gestión de una IPS/red hospitalaria
A7: 1 | B7: Electiva de humanidades I | C7: Humanidades | D7: — | E7: — | F7: No encaja
A8: 1 | B8: Bive I | C8: Bienestar/Formación integral | D8: — | E8: — | F8: No encaja
A9: 2 | B9: Sistema de Seguridad Social | C9: Salud | D9: — | E9: — | F9: No encaja
A10: 2 | B10: Electiva de humanidades II | C10: Humanidades | D10: — | E10: — | F10: No encaja
A11: 2 | B11: Sistemas de información gerencial | C11: Digital | D11: — | E11: — | F11: No encaja
A12: 2 | B12: Legislación en Salud | C12: Jurídica | D12: — | E12: — | F12: No encaja
A13: 2 | B13: Salud pública I | C13: Salud | D13: — | E13: — | F13: No encaja
A14: 2 | B14: Bive II | C14: Bienestar/Formación integral | D14: — | E14: — | F14: No encaja
A15: 3 | B15: Estadística para la toma de decisiones – análisis de datos | C15: Cuantitativa | D15: — | E15: — | F15: No encaja
A16: 3 | B16: Electiva de humanidades III | C16: Humanidades | D16: — | E16: — | F16: No encaja
A17: 3 | B17: Salud Pública II | C17: Salud | D17: — | E17: — | F17: No encaja
A18: 3 | B18: Organización y Management | C18: Administración | D18: Business21 | E18: N3-4 | F18: Encaje perfecto
... A21: 4 | B21: Administración Estratégica | C21: Administración | D21: — | E21: — | F21: No encaja
A22: 4 | B22: Matemática financiera | C22: Cuantitativa | D22: Advisor Jr. | E22: N1-2 | F22: Encaje parcial | G22: Calculadora financiera / casos de valor del dinero en el tiempo
A23: 4 | B23: Servicios asistenciales hospitalarios | C23: Salud | D23: — | E23: — | F23: No encaja | G23: Simulador de operación de un servicio hospitalario
A24: 4 | B24: Gestión de la Cadena de Suministro | C24: Operaciones | D24: — | E24: — | F24: No encaja
A25: 4 | B25: Economía para la Toma de Decisiones | C25: Economía | D25: — | E25: — | F25: No encaja
A26: 4 | B26: Bive IV | C26: Bienestar/Formación integral | D26: — | E26: — | F26: No encaja
A27: 5 | B27: Gestión de calidad en salud | C27: Salud | D27: — | E27: — | F27: No encaja | G27: Simulador de gestión de calidad y acreditación en salud
A28: 5 | B28: Sistemas de Información en Salud | C28: Digital | D28: — | E28: — | F28: No encaja
A29: 5 | B29: Costos y presupuestos en salud | C29: Finanzas | D29: Corbatul | E29: N3-4 | F29: Encaje parcial
A30: 5 | B30: Suficiencia en segundo idioma I | C30: Idiomas | D30: — | E30: — | F30: No encaja
A31: 5 | B31: Procesos de Talento Humano | C31: Talento Humano | D31: — | E31: — | F31: No encaja
A32: 5 | B32: Electiva Gerencial I | C32: Electiva | D32: — | E32: — | F32: No encaja | G32: Contenido variable según la línea gerencial elegida; evaluar caso a caso
A33: 6 | B33: Gestión de la Seguridad y Salud en el Trabajo | C33: Salud | D33: — | E33: — | F33: No encaja
A34: 6 | B34: Contratación en Salud | C34: Salud | D34: — | E34: — | F34: No encaja
A35: 6 | B35: Suficiencia en segundo idioma II | C35: Idiomas | D35: — | E35: — | F35: No encaja
A36: 6 | B36: Electiva de Profundización I | C36: Electiva | D36: — | E36: — | F36: No encaja | G36: Contenido variable según la línea de profundización elegida; evaluar caso a caso
A37: 6 | B37: Health Management | C37: Salud | D37: — | E37: — | F37: No encaja | G37: Simulador de dirección de instituciones prestadoras de salud (IPS)
A38: 6 | B38: Electiva gerencial II | C38: Electiva | D38: — | E38: — | F38: No encaja | G38: Contenido variable según la línea gerencial elegida; evaluar caso a caso
A39: 7 | B39: Suficiencia en segundo idioma III | C39: Idiomas | D39: — | E39: — | F39: No encaja
A40: 7 | B40: Electiva de Profundización II | C40: Electiva | D40: — | E40: — | F40: No encaja | G40: Contenido variable según la línea de profundización elegida; evaluar caso a caso
A41: 7 | B41: Electiva de Profundización III | C41: Electiva | D41: — | E41: — | F41: No encaja | G41: Contenido variable según la línea de profundización elegida; evaluar caso a caso
A42: 7 | B42: Evaluación y control de procesos y servicios de salud | C42: Salud | D42: — | E42: — | F42: No encaja
...

Sheet Contaduría Pública
A1: Contaduría Pública · Corporación Universitaria de la Costa (CUC) — presencial, Barranquilla
A2: Semestre | B2: Materia | C2: Área temática | D2: Simulador CompanyGame que encaja | E2: Nivel CG | F2: Grado de ajuste | G2: Tipo de simulador a desarrollar (si no encaja / parcial) | H2: Observación
A3: 1 | B3: Bive I | C3: Bienestar/Formación integral | D3: — | E3: — | F3: No encaja
A4: 1 | B4: Contabilidad Financiera I | C4: Contabilidad | D4: — | E4: — | F4: No encaja
A5: 1 | B5: Entorno Empresarial y Contable | C5: Contabilidad | D5: — | E5: — | F5: No encaja
A6: 1 | B6: Electiva de Humanidades I | C6: Humanidades | D6: — | E6: — | F6: No encaja
A7: 1 | B7: Legislación Comercial | C7: Jurídica | D7: — | E7: — | F7: No encaja
A8: 1 | B8: Matemáticas | C8: Cuantitativa | D8: — | E8: — | F8: No encaja
A9: 2 | B9: Bive II | C9: Bienestar/Formación integral | D9: — | E9: — | F9: No encaja
A10: 2 | B10: Contabilidad Financiera II | C10: Contabilidad | D10: ContaTrainer | E10: N1-2 | F10: Encaje perfecto
A11: 2 | B11: Electiva de Humanidades II | C11: Humanidades | D11: — | E11: — | F11: No encaja
A12: 2 | B12: Legislación Laboral | C12: Jurídica | D12: — | E12: — | F12: No encaja
A13: 2 | B13: Matemática Financiera | C13: Cuantitativa | D13: Advisor Jr. | E13: N1-2 | F13: Encaje parcial | G13: Calculadora financiera / casos de valor del dinero en el tiempo
A14: 2 | B14: Teoría Económica | C14: Economía | D14: — | E14: — | F14: No encaja
A15: 3 | B15: Bive III | C15: Bienestar/Formación integral | D15: — | E15: — | F15: No encaja
A16: 3 | B16: Código de Ética del Ejercicio Profesional | C16: Ética | D16: — | E16: — | F16: No encaja
A17: 3 | B17: Contabilidad Financiera III | C17: Contabilidad | D17: — | E17: — | F17: No encaja
A18: 3 | B18: Dinámicas de Integración Global | C18: Internacional | D18: — | E18: — | F18: No encaja
A19: 3 | B19: Electiva de Humanidades III | C19: Humanidades | D19: — | E19: — | F19: No encaja
A20: 3 | B20: Estadística Organizacional | C20: Cuantitativa | D20: — | E20: — | F20: No encaja
A21: 3 | B21: Fundamentos Tributarios | C21: Jurídica | D21: — | E21: — | F21: No encaja | G21: Simulador de liquidación de impuestos básicos
A22: 3 | B22: Sistema de Información Contable | C22: Digital | D22: — | E22: — | F22: No encaja
A23: 4 | B23: Bive IV | C23: Bienestar/Formación integral | D23: — | E23: — | F23: No encaja
A24: 4 | B24: Contabilidad Financiera IV | C24: Contabilidad | D24: — | E24: — | F24: No encaja
A25: 4 | B25: Contabilidad Social y Costos Ambientales | C25: Sostenibilidad/ESG | D25: ESG Project | E25: N3-4 | F25: Encaje parcial
A26: 4 | B26: Gerencia Financiera | C26: Finanzas | D26: — | E26: — | F26: No encaja
A27: 4 | B27: Gestión Tributaria I | C27: Jurídica | D27: — | E27: — | F27: No encaja
A28: 4 | B28: Investigación Contable | C28: Investigación | D28: — | E28: — | F28: No encaja
A29: 4 | B29: Risk Assesments And Internal Control | C29: Finanzas | D29: — | E29: — | F29: No encaja | G29: Simulador de auditoría de riesgos y control interno
A30: 5 | B30: Auditoría Financiera | C30: Finanzas | D30: — | E30: — | F30: No encaja | G30: Simulador de auditoría financiera (papeles de trabajo, hallazgos)
A31: 5 | B31: Consultoría Contable | C31: Contabilidad | D31: — | E31: — | F31: No encaja
A32: 5 | B32: Costos y Creación de Valor Empresarial | C32: Finanzas | D32: Corbatul | E32: N3-4 | F32: Encaje perfecto
A33: 5 | B33: Electiva Gerencial I | C33: Electiva | D33: — | E33: — | F33: No encaja | G33: Contenido variable según la línea gerencial elegida; evaluar caso a caso
A34: 5 | B34: Gestión Tributaria II | C34: Jurídica | D34: — | E34: — | F34: No encaja
A35: 5 | B35: Software de Auditoría y Análisis de Datos | C35: Digital | D35: — | E35: — | F35: No encaja
A36: 5 | B36: Suficiencia en segundo Idioma I | C36: Idiomas | D36: — | E36: — | F36: No encaja
A37: 6 | B37: Dirección de Costos para la Competitividad Empresarial | C37: Finanzas | D37: — | E37: — | F37: No encaja
A38: 6 | B38: Electiva Gerencial II | C38: Electiva | D38: — | E38: — | F38: No encaja | G38: Contenido variable según la línea gerencial elegida; evaluar caso a caso
A39: 6 | B39: Gestión Contable y Financiera Pública | C39: Sector Público | D39: — | E39: — | F39: No encaja
A40: 6 | B40: Modelos de Costeo y Rentabilidad Empresarial | C40: Finanzas | D40: — | E40: — | F40: No encaja
...

Sheet Mercadeo y Publicidad
A1: Mercadeo y Publicidad · Corporación Universitaria de la Costa (CUC) — presencial, Barranquilla
A2: Semestre | B2: Materia | C2: Área temática | D2: Simulador CompanyGame que encaja | E2: Nivel CG | F2: Grado de ajuste | G2: Tipo de simulador a desarrollar (si no encaja / parcial) | H2: Observación
A3: 1 | B3: Mercadeo y creación de valor | C3: Marketing | D3: Coffee Time | E3: N1-2 | F3: Encaje perfecto
A4: 1 | B4: Publicidad y creatividad | C4: Comunicación | D4: — | E4: — | F4: No encaja | G4: Simulador de creación y evaluación de campañas publicitarias
A5: 1 | B5: Gestión organizacional ágil | C5: Administración | D5: — | E5: — | F5: No encaja
A6: 1 | B6: Razonamiento lógico matemático | C6: Cuantitativa | D6: — | E6: — | F6: No encaja
A7: 1 | B7: Electiva de Humanidades I | C7: Humanidades | D7: — | E7: — | F7: No encaja
A8: 1 | B8: BIVE I | C8: Bienestar/Formación integral | D8: — | E8: — | F8: No encaja
A9: 2 | B9: Cultura del consumidor | C9: Marketing | D9: — | E9: — | F9: No encaja
A10: 2 | B10: Contabilidad financiera | C10: Contabilidad | D10: ContaTrainer | E10: N1-2 | F10: Encaje perfecto
A11: 2 | B11: Estadística para la gestión | C11: Cuantitativa | D11: — | E11: — | F11: No encaja
A12: 2 | B12: Electiva de Humanidades II | C12: Humanidades | D12: — | E12: — | F12: No encaja
A13: 2 | B13: Semiótica y persuasión publicitaria | C13: Comunicación | D13: — | E13: — | F13: No encaja
A14: 2 | B14: BIVE II | C14: Bienestar/Formación integral | D14: — | E14: — | F14: No encaja
A15: 3 | B15: Estrategia de producto y precio | C15: Marketing | D15: Food Company | E15: N3-4 | F15: Encaje parcial
A16: 3 | B16: Escritura creativa publicitaria | C16: Comunicación | D16: — | E16: — | F16: No encaja
A17: 3 | B17: Identidad visual de marca | C17: Comunicación | D17: — | E17: — | F17: No encaja | G17: Herramienta de diseño de identidad de marca
A18: 3 | B18: Entorno económico | C18: Economía | D18: — | E18: — | F18: No encaja
A19: 3 | B19: Costos y presupuestos | C19: Finanzas | D19: Corbatul | E19: N3-4 | F19: Encaje parcial
A20: 3 | B20: Electiva de humanidades III | C20: Humanidades | D20: — | E20: — | F20: No encaja
A21: 3 | B21: BIVE III | C21: Bienestar/Formación integral | D21: — | E21: — | F21: No encaja
A22: 4 | B22: Estrategia de canales y promoción | C22: Marketing | D22: SalesManager | E22: N3-4 | F22: Encaje parcial
A23: 4 | B23: Estrategia de marca | C23: Marketing | D23: — | E23: — | F23: No encaja | G23: Simulador de gestión estratégica de marca (brand equity)
A24: 4 | B24: Diseño gráfico digital | C24: Comunicación | D24: — | E24: — | F24: No encaja
A25: 4 | B25: Advertising Photography | C25: Comunicación | D25: — | E25: — | F25: No encaja
A26: 4 | B26: Transformación digital e IA | C26: Digital | D26: — | E26: — | F26: No encaja
A27: 4 | B27: Dinámicas de integración global | C27: Internacional | D27: — | E27: — | F27: No encaja
A28: 4 | B28: BIVE IV | C28: Bienestar/Formación integral | D28: — | E28: — | F28: No encaja
A29: 5 | B29: Investigación cuantitativa de mercados | C29: Investigación | D29: — | E29: — | F29: No encaja
A30: 5 | B30: Diseño publicitario digital | C30: Comunicación | D30: — | E30: — | F30: No encaja
A31: 5 | B31: Estrategia digital y social media | C31: Digital | D31: — | E31: — | F31: No encaja | G31: Simulador de gestión de campañas en redes sociales
A32: 5 | B32: Innovación sostenible | C32: Sostenibilidad/ESG | D32: ESG Project | E32: N3-4 | F32: Encaje parcial
A33: 5 | B33: Electiva gerencial I | C33: Electiva | D33: — | E33: — | F33: No encaja | G33: Contenido variable según la línea gerencial elegida; evaluar caso a caso
A34: 5 | B34: Suficiencia en segundo idioma I | C34: Idiomas | D34: — | E34: — | F34: No encaja
A35: 6 | B35: Investigación cualitativa de mercados | C35: Investigación | D35: FOCUS | E35: N5 | F35: Encaje perfecto
A36: 6 | B36: Dirección estratégica de mercadeo | C36: Marketing | D36: GlobalMarket | E36: N6-7 | F36: Encaje perfecto
A37: 6 | B37: Dirección creativa publicitaria | C37: Comunicación | D37: — | E37: — | F37: No encaja
A38: 6 | B38: Estrategia y plan de medios | C38: Comunicación | D38: — | E38: — | F38: No encaja | G38: Simulador de planificación de medios y presupuesto de pauta
A39: 6 | B39: Electiva gerencial II | C39: Electiva | D39: — | E39: — | F39: No encaja | G39: Contenido variable según la línea gerencial elegida; evaluar caso a caso
A40: 6 | B40: Suficiencia en segundo idioma II | C40: Idiomas | D40: — | E40: — | F40: No encaja
...

Sheet Negocios Internacionales
A1: Negocios Internacionales · Corporación Universitaria de la Costa (CUC) — presencial, Barranquilla
A2: Semestre | B2: Materia | C2: Área temática | D2: Simulador CompanyGame que encaja | E2: Nivel CG | F2: Grado de ajuste | G2: Tipo de simulador a desarrollar (si no encaja / parcial) | H2: Observación
A3: 1 | B3: Matemáticas I | C3: Cuantitativa | D3: — | E3: — | F3: No encaja
A4: 1 | B4: Negocios internacionales | C4: Internacional | D4: Inter Pyme | E4: N3-4 | F4: Encaje parcial
A5: 1 | B5: Teoría económica | C5: Economía | D5: — | E5: — | F5: No encaja
A6: 1 | B6: Electiva de humanidades I | C6: Humanidades | D6: — | E6: — | F6: No encaja
A7: 1 | B7: Suficiencia segundo idioma I | C7: Idiomas | D7: — | E7: — | F7: No encaja
A8: 1 | B8: BIVE I | C8: Bienestar/Formación integral | D8: — | E8: — | F8: No encaja
A9: 2 | B9: Análisis de datos financieros | C9: Finanzas | D9: — | E9: — | F9: No encaja
A10: 2 | B10: Dinámicas de integración global | C10: Internacional | D10: — | E10: — | F10: No encaja
A11: 2 | B11: Economía para la toma de decisiones | C11: Economía | D11: — | E11: — | F11: No encaja
A12: 2 | B12: Mercadeo y creación de valor | C12: Marketing | D12: Coffee Time | E12: N1-2 | F12: Encaje perfecto
A13: 2 | B13: Electiva de humanidades II | C13: Humanidades | D13: — | E13: — | F13: No encaja
A14: 2 | B14: Suficiencia de segundo idioma II | C14: Idiomas | D14: — | E14: — | F14: No encaja
... A16: 3 | B16: Estadística para la toma de decisiones | C16: Cuantitativa | D16: — | E16: — | F16: No encaja
A17: 3 | B17: Estrategia intercultural global | C17: Internacional | D17: — | E17: — | F17: No encaja | G17: Simulador de negociación y gestión de equipos multiculturales
A18: 3 | B18: Matemáticas financieras | C18: Cuantitativa | D18: Advisor Jr. | E18: N1-2 | F18: Encaje parcial
A19: 3 | B19: Introducción a los procesos logísticos | C19: Comercio Exterior | D19: — | E19: — | F19: No encaja | G19: Simulador de cadena logística de comercio exterior
A20: 3 | B20: Suficiencia de segundo idioma III | C20: Idiomas | D20: — | E20: — | F20: No encaja
A21: 3 | B21: Electiva de Humanidades III | C21: Humanidades | D21: — | E21: — | F21: No encaja
A22: 3 | B22: BIVE III | C22: Bienestar/Formación integral | D22: — | E22: — | F22: No encaja
A23: 4 | B23: Relaciones Internacionales | C23: Internacional | D23: — | E23: — | F23: No encaja
A24: 4 | B24: Legislación aduanera y cambiaria | C24: Comercio Exterior | D24: — | E24: — | F24: No encaja
A25: 4 | B25: Gestión de compras e inventarios | C25: Operaciones | D25: — | E25: — | F25: No encaja
A26: 4 | B26: Finanzas internacionales | C26: Finanzas | D26: — | E26: — | F26: No encaja
A27: 4 | B27: Suficiencia segundo idioma IV | C27: Idiomas | D27: — | E27: — | F27: No encaja
A28: 4 | B28: Electiva Gerencial I | C28: Electiva | D28: — | E28: — | F28: No encaja | G28: Contenido variable según la línea gerencial elegida; evaluar caso a caso
A29: 4 | B29: BIVE IV | C29: Bienestar/Formación integral | D29: — | E29: — | F29: No encaja
A30: 5 | B30: Geopolitics | C30: Internacional | D30: — | E30: — | F30: No encaja
A31: 5 | B31: Gerencia de la cadena de suministro | C31: Operaciones | D31: — | E31: — | F31: No encaja
A32: 5 | B32: Procesos de importación | C32: Comercio Exterior | D32: — | E32: — | F32: No encaja
A33: 5 | B33: Analítica de datos para la toma de decisiones | C33: Cuantitativa | D33: — | E33: — | F33: No encaja
A34: 5 | B34: International Negotiation | C34: Internacional | D34: — | E34: — | F34: No encaja | G34: Simulador de negociación comercial internacional
A35: 5 | B35: Electiva Gerencial II | C35: Electiva | D35: — | E35: — | F35: No encaja | G35: Contenido variable según la línea gerencial elegida; evaluar caso a caso
A36: 6 | B36: Dirección estratégica de mercadeo | C36: Marketing | D36: — | E36: — | F36: No encaja
A37: 6 | B37: Liderazgo global y gobernanza | C37: Internacional | D37: — | E37: — | F37: No encaja
A38: 6 | B38: Procesos de exportación | C38: Comercio Exterior | D38: — | E38: — | F38: No encaja
A39: 6 | B39: Global marketing | C39: Marketing | D39: — | E39: — | F39: No encaja
A40: 6 | B40: Electiva de profundización I | C40: Electiva | D40: — | E40: — | F40: No encaja | G40: Contenido variable según la línea de profundización elegida; evaluar caso a caso
A41: 6 | B41: Electiva Gerencial III | C41: Electiva | D41: — | E41: — | F41: No encaja | G41: Contenido variable según la línea gerencial elegida; evaluar caso a caso
...
